<?xml version="1.0" ?>
<!--This file contains the SDF model of a KUKA iiwa robot with a wsg50 gripper.
    It has been produced from the varients in //third_party/robotics/models.
    Note:  This file is temporary, and should be deleted once Bullet supports
    importing models in SDF.  Also, this file has been specialized for Bullet,
    because the mass of the base link has been set to 0, as needed by Bullet.
    Note:  All of the gripper link poses have been adjusted in the z direction
    to achieve a reasonable position of the gripper relative to the arm.
    Note: The joint names for the KUKA have been changed to J0, J1, etc. -->
<sdf version='1.6'>
    <world name='default'>
        <model name='lbr_iiwa_with_wsg50'>

            <link name="base_world">
                <pose frame=''>0 0 0 0 -0 0</pose>
                <inertial>
                    <pose frame=''>0 0 0 0 -0 0</pose>
                    <mass>0</mass>
                    <inertia>
                        <ixx>1</ixx>
                        <ixy>0</ixy>
                        <ixz>0</ixz>
                        <iyy>1</iyy>
                        <iyz>0</iyz>
                        <izz>1</izz>
                    </inertia>
                </inertial>
            </link>

            <link name="x">
                <pose frame=''>0 0 0 0 -0 0</pose>
                <inertial>
                    <pose frame=''>0 0 0 0 -0 0</pose>
                    <mass>0</mass>
                    <inertia>
                        <ixx>1</ixx>
                        <ixy>0</ixy>
                        <ixz>0</ixz>
                        <iyy>1</iyy>
                        <iyz>0</iyz>
                        <izz>1</izz>
                    </inertia>
                </inertial>
            </link>

            <joint name="x_joint" type="prismatic">
                <parent>base_world</parent>
                <child>x</child>
                <axis>
                    <xyz>1 0 0</xyz>
                    <limit>
                        <lower>-10</lower>
                        <upper>10</upper>
                        <effort>1000</effort>
                        <velocity>0.01</velocity>
                    </limit>
                    <dynamics>
                        <damping>0</damping>
                        <friction>0</friction>
                        <spring_reference>0</spring_reference>
                        <spring_stiffness>0</spring_stiffness>
                    </dynamics>
                </axis>
            </joint>

            <link name="y">
                <pose frame=''>0 0 0 0 -0 0</pose>
                <inertial>
                    <pose frame=''>0 0 0 0 -0 0</pose>
                    <mass>0</mass>
                    <inertia>
                        <ixx>1</ixx>
                        <ixy>0</ixy>
                        <ixz>0</ixz>
                        <iyy>1</iyy>
                        <iyz>0</iyz>
                        <izz>1</izz>
                    </inertia>
                </inertial>
            </link>

            <joint name="y_joint" type="prismatic">
                <parent>x</parent>
                <child>y</child>
                <axis>
                    <xyz>0 1 0</xyz>
                    <limit>
                        <lower>-10</lower>
                        <upper>10</upper>
                        <effort>1000</effort>
                        <velocity>0.01</velocity>
                    </limit>
                    <dynamics>
                        <damping>0</damping>
                        <friction>0</friction>
                        <spring_reference>0</spring_reference>
                        <spring_stiffness>0</spring_stiffness>
                    </dynamics>
                </axis>
            </joint>

            <link name="z">
                <pose frame=''>0 0 0 0 -0 0</pose>
                <inertial>
                    <pose frame=''>0 0 0 0 -0 0</pose>
                    <mass>0</mass>
                    <inertia>
                        <ixx>1</ixx>
                        <ixy>0</ixy>
                        <ixz>0</ixz>
                        <iyy>1</iyy>
                        <iyz>0</iyz>
                        <izz>1</izz>
                    </inertia>
                </inertial>
            </link>

            <joint name="z_joint" type="prismatic">
                <parent>y</parent>
                <child>z</child>
                <axis>
                    <xyz>0 0 1</xyz>
                    <limit>
                        <lower>-10</lower>
                        <upper>10</upper>
                        <effort>1000</effort>
                        <velocity>0.01</velocity>
                    </limit>
                    <dynamics>
                        <damping>0</damping>
                        <friction>0</friction>
                        <spring_reference>0</spring_reference>
                        <spring_stiffness>0</spring_stiffness>
                    </dynamics>
                </axis>
            </joint>

            <link name="roll">
                <pose frame=''>0 0 0 0 -0 0</pose>
                <inertial>
                    <pose frame=''>0 0 0 0 -0 0</pose>
                    <mass>0</mass>
                    <inertia>
                        <ixx>1</ixx>
                        <ixy>0</ixy>
                        <ixz>0</ixz>
                        <iyy>1</iyy>
                        <iyz>0</iyz>
                        <izz>1</izz>
                    </inertia>
                </inertial>
            </link>

            <joint name="roll_joint" type="fixed">
                <parent>z</parent>
                <child>roll</child>
            </joint>

            <link name="pitch">
                <pose frame=''>0 0 0 0 -0 0</pose>
                <inertial>
                    <pose frame=''>0 0 0 0 -0 0</pose>
                    <mass>0</mass>
                    <inertia>
                        <ixx>1</ixx>
                        <ixy>0</ixy>
                        <ixz>0</ixz>
                        <iyy>1</iyy>
                        <iyz>0</iyz>
                        <izz>1</izz>
                    </inertia>
                </inertial>
            </link>

            <joint name="pitch_joint" type="fixed">
                <parent>roll</parent>
                <child>pitch</child>
            </joint>

            <link name="yaw">
                <pose frame=''>0 0 0 0 -0 0</pose>
                <inertial>
                    <pose frame=''>0 0 0 0 -0 0</pose>
                    <mass>0</mass>
                    <inertia>
                        <ixx>1</ixx>
                        <ixy>0</ixy>
                        <ixz>0</ixz>
                        <iyy>1</iyy>
                        <iyz>0</iyz>
                        <izz>1</izz>
                    </inertia>
                </inertial>
            </link>

            <joint name="yaw_joint" type="revolute">
                <parent>pitch</parent>
                <child>yaw</child>
                <axis>
                    <xyz>0 0 1</xyz>
                    <limit>
                        <lower>-3.1415927</lower>
                        <upper>3.1415927</upper>
                        <effort>1000</effort>
                        <velocity>0.01</velocity>
                    </limit>
                    <dynamics>
                        <damping>0</damping>
                        <friction>0</friction>
                        <spring_reference>0</spring_reference>
                        <spring_stiffness>0</spring_stiffness>
                    </dynamics>
                </axis>
            </joint>

            <link name='base_link'>
                <pose frame=''>0 0 0 0 -0 0</pose>
                <inertial>
                    <pose frame=''>0 0 0 0 -0 0</pose>
                    <mass>0.2</mass>
                    <inertia>
                        <ixx>1</ixx>
                        <ixy>0</ixy>
                        <ixz>0</ixz>
                        <iyy>1</iyy>
                        <iyz>0</iyz>
                        <izz>1</izz>
                    </inertia>
                </inertial>
                <visual name='base_link_visual'>
                    <pose frame=''>0 0 0 0 0 0</pose>
                    <geometry>
                        <box>
                            <size>0.05 0.05 0.1</size>
                        </box>
                    </geometry>
                    <material>
                        <ambient>1 0 0 1</ambient>
                        <diffuse>0.6 0.6 0.6 1</diffuse>
                        <specular>0.5 0.5 0.5 1</specular>
                        <emissive>0 0 0 0</emissive>
                    </material>
                </visual>
                <collision name='base_link_collision'>
                    <pose frame=''>0 0 0 0 0 0</pose>
                    <geometry>
                        <box>
                            <size>0.05 0.05 0.1</size>
                        </box>
                    </geometry>
                    <material>
                        <ambient>1 0 0 1</ambient>
                        <diffuse>0.6 0.6 0.6 1</diffuse>
                        <specular>0.5 0.5 0.5 1</specular>
                        <emissive>0 0 0 0</emissive>
                    </material>
                </collision>
            </link>

            <joint name='base_link_joint' type='fixed'>
                <parent>yaw</parent>
                <child>base_link</child>
            </joint>

            <link name='left_finger'>
                <pose frame=''>0 0 0.045 0 -0.05 0</pose>
                <inertial>
                    <pose frame=''>0 0 0.04 0 0 0</pose>
                    <mass>0.2</mass>
                    <inertia>
                        <ixx>0.1</ixx>
                        <ixy>0</ixy>
                        <ixz>0</ixz>
                        <iyy>0.1</iyy>
                        <iyz>0</iyz>
                        <izz>0.1</izz>
                    </inertia>
                </inertial>
                <visual name='left_finger_visual'>
                    <pose frame=''>0 0 0.04 0 0 0</pose>
                    <geometry>
                        <box>
                            <size>0.01 0.01 0.08</size>
                        </box>
                    </geometry>
                    <material>
                        <ambient>1 0 0 1</ambient>
                        <diffuse>0.6 0.6 0.6 1</diffuse>
                        <specular>0.5 0.5 0.5 1</specular>
                        <emissive>0 0 0 0</emissive>
                    </material>
                </visual>
                <collision name='left_finger_collision'>
                    <pose frame=''>0 0 0.04 0 0 0</pose>
                    <geometry>
                        <box>
                            <size>0.01 0.01 0.08</size>
                        </box>
                    </geometry>
                </collision>
            </link>

            <joint name='base_left_finger_joint' type='revolute'>
                <parent>base_link</parent>
                <child>left_finger</child>
                <axis>
                    <xyz>0 1 0</xyz>
                    <limit>
                        <lower>-10</lower>
                        <upper>10</upper>
                        <effort>1000</effort>
                        <velocity>0.1</velocity>
                    </limit>
                    <dynamics>
                        <damping>0</damping>
                        <friction>0</friction>
                        <spring_reference>0</spring_reference>
                        <spring_stiffness>0</spring_stiffness>
                    </dynamics>
                </axis>
            </joint>

            <joint name='left_finger_base_joint' type='fixed'>
                <parent>left_finger</parent>
                <child>left_finger_base</child>
            </joint>

            <link name='left_finger_base'>
                <contact>
                    <lateral_friction>0.8</lateral_friction>
                    <spinning_friction>.1</spinning_friction>
                </contact>
                <pose frame=''>-0.005 0 0.125 0 -0.3 0</pose>
                <inertial>
                    <pose frame=''>-0.003 0 0.04 0 0 0</pose>
                    <mass>0.2</mass>
                    <inertia>
                        <ixx>0.1</ixx>
                        <ixy>0</ixy>
                        <ixz>0</ixz>
                        <iyy>0.1</iyy>
                        <iyz>0</iyz>
                        <izz>0.1</izz>
                    </inertia>
                </inertial>
                <visual name='left_finger_base_visual'>
                    <pose frame=''>0 0 0 0 0 0</pose>
                    <geometry>
                        <mesh>
                            <scale>1 1 1</scale>
                            <uri>meshes/finger_base_left.stl</uri>
                        </mesh>
                    </geometry>
                    <material>
                        <ambient>1 0 0 1</ambient>
                        <diffuse>0.6 0.6 0.6 1</diffuse>
                        <specular>0.5 0.5 0.5 1</specular>
                        <emissive>0 0 0 0</emissive>
                    </material>
                </visual>
                <collision name='left_finger_base_collision'>
                    <pose frame=''>0 0 0 0 0 0</pose>
                    <geometry>
                        <mesh>
                            <scale>1 1 1</scale>
                            <uri>meshes/finger_base_left.stl</uri>
                        </mesh>
                    </geometry>
                </collision>
            </link>

            <joint name='left_base_tip_joint' type='revolute'>
                <parent>left_finger_base</parent>
                <child>left_finger_tip</child>
                <axis>
                    <xyz>0 1 0</xyz>
                    <limit>
                        <lower>-10</lower>
                        <upper>10</upper>
                        <effort>1000</effort>
                        <velocity>0.1</velocity>
                    </limit>
                    <dynamics>
                        <damping>0</damping>
                        <friction>0</friction>
                        <spring_reference>0</spring_reference>
                        <spring_stiffness>0</spring_stiffness>
                    </dynamics>
                </axis>
            </joint>

            <link name='left_finger_tip'>
                <contact>
                    <lateral_friction>0.8</lateral_friction>
                    <spinning_friction>.1</spinning_friction>
                </contact>
                <pose frame=''>-0.02 0 0.185 0 0.2 0</pose>
                <inertial>
                    <pose frame=''>-0.005 0 0.026 0 0 0</pose>
                    <mass>0.2</mass>
                    <inertia>
                        <ixx>0.1</ixx>
                        <ixy>0</ixy>
                        <ixz>0</ixz>
                        <iyy>0.1</iyy>
                        <iyz>0</iyz>
                        <izz>0.1</izz>
                    </inertia>
                </inertial>
                <visual name='left_finger_tip_visual'>
                    <pose frame=''>0 0 0 0 0 0</pose>
                    <geometry>
                        <mesh>
                            <scale>1 1 1</scale>
                            <uri>meshes/finger_tip_left.stl</uri>
                        </mesh>
                    </geometry>
                    <material>
                        <ambient>1 0 0 1</ambient>
                        <diffuse>0.6 0.6 0.6 1</diffuse>
                        <specular>0.5 0.5 0.5 1</specular>
                        <emissive>0 0 0 0</emissive>
                    </material>
                </visual>
                <collision name='left_finger_tip_collision'>
                    <pose frame=''>0 0 0 0 0 0</pose>
                    <geometry>
                        <mesh>
                            <scale>1 1 1</scale>
                            <uri>meshes/finger_tip_left.stl</uri>
                        </mesh>
                    </geometry>
                </collision>
            </link>

            <joint name='base_right_finger_joint' type='revolute'>
                <parent>base_link</parent>
                <child>right_finger</child>
                <axis>
                    <xyz>0 1 0</xyz>
                    <limit>
                        <lower>-10</lower>
                        <upper>10</upper>
                        <effort>1000</effort>
                        <velocity>0.1</velocity>
                    </limit>
                    <dynamics>
                        <damping>0</damping>
                        <friction>0</friction>
                        <spring_reference>0</spring_reference>
                        <spring_stiffness>0</spring_stiffness>
                    </dynamics>
                </axis>
            </joint>

            <link name='right_finger'>
                <contact>
                    <lateral_friction>0.8</lateral_friction>
                    <spinning_friction>.1</spinning_friction>
                </contact>
                <pose frame=''>0 0 0.045 0 0.05 0</pose>
                <inertial>
                    <pose frame=''>0 0 0.04 0 0 0</pose>
                    <mass>0.2</mass>
                    <inertia>
                        <ixx>0.1</ixx>
                        <ixy>0</ixy>
                        <ixz>0</ixz>
                        <iyy>0.1</iyy>
                        <iyz>0</iyz>
                        <izz>0.1</izz>
                    </inertia>
                </inertial>
                <visual name='right_finger_visual'>
                    <pose frame=''>0 0 0.04 0 0 0</pose>
                    <geometry>
                        <box>
                            <size>0.01 0.01 0.08</size>
                        </box>
                    </geometry>
                    <material>
                        <ambient>1 0 0 1</ambient>
                        <diffuse>0.6 0.6 0.6 1</diffuse>
                        <specular>0.5 0.5 0.5 1</specular>
                        <emissive>0 0 0 0</emissive>
                    </material>
                </visual>
                <collision name='right_finger_collision'>
                    <pose frame=''>0 0 0.04 0 0 0</pose>
                    <geometry>
                        <box>
                            <size>0.01 0.01 0.08</size>
                        </box>
                    </geometry>
                    <material>
                        <ambient>1 0 0 1</ambient>
                        <diffuse>0.6 0.6 0.6 1</diffuse>
                        <specular>0.5 0.5 0.5 1</specular>
                        <emissive>0 0 0 0</emissive>
                    </material>
                </collision>
            </link>

            <joint name='right_finger_base_joint' type='fixed'>
                <parent>right_finger</parent>
                <child>right_finger_base</child>
            </joint>

            <link name='right_finger_base'>
                <contact>
                    <lateral_friction>0.8</lateral_friction>
                    <spinning_friction>.1</spinning_friction>
                </contact>
                <pose frame=''>0.005 0 0.125 0 0.3 0</pose>
                <inertial>
                    <pose frame=''>0.003 0 0.04 0 0 0</pose>
                    <mass>0.2</mass>
                    <inertia>
                        <ixx>0.1</ixx>
                        <ixy>0</ixy>
                        <ixz>0</ixz>
                        <iyy>0.1</iyy>
                        <iyz>0</iyz>
                        <izz>0.1</izz>
                    </inertia>
                </inertial>
                <visual name='right_finger_base_visual'>
                    <pose frame=''>0 0 0 0 0 0</pose>
                    <geometry>
                        <mesh>
                            <scale>1 1 1</scale>
                            <uri>meshes/finger_base_right.stl</uri>
                        </mesh>
                    </geometry>
                    <material>
                        <ambient>1 0 0 1</ambient>
                        <diffuse>0.6 0.6 0.6 1</diffuse>
                        <specular>0.5 0.5 0.5 1</specular>
                        <emissive>0 0 0 0</emissive>
                    </material>
                </visual>
                <collision name='right_finger_base_collision'>
                    <pose frame=''>0 0 0 0 0 0</pose>
                    <geometry>
                        <mesh>
                            <scale>1 1 1</scale>
                            <uri>meshes/finger_base_right.stl</uri>
                        </mesh>
                    </geometry>
                </collision>
            </link>

            <joint name='right_base_tip_joint' type='revolute'>
                <parent>right_finger_base</parent>
                <child>right_finger_tip</child>
                <axis>
                    <xyz>0 1 0</xyz>
                    <limit>
                        <lower>-10</lower>
                        <upper>10</upper>
                        <effort>1000</effort>
                        <velocity>0.1</velocity>
                    </limit>
                    <dynamics>
                        <damping>0</damping>
                        <friction>0</friction>
                        <spring_reference>0</spring_reference>
                        <spring_stiffness>0</spring_stiffness>
                    </dynamics>
                </axis>
            </joint>

            <link name='right_finger_tip'>
                <contact>
                    <lateral_friction>0.8</lateral_friction>
                    <spinning_friction>.1</spinning_friction>
                </contact>
                <pose frame=''>0.02 0 0.185 0 -0.2 0</pose>
                <inertial>
                    <pose frame=''>0.005 0 0.026 0 0 0</pose>
                    <mass>0.2</mass>
                    <inertia>
                        <ixx>0.1</ixx>
                        <ixy>0</ixy>
                        <ixz>0</ixz>
                        <iyy>0.1</iyy>
                        <iyz>0</iyz>
                        <izz>0.1</izz>
                    </inertia>
                </inertial>
                <visual name='right_finger_visual'>
                    <pose frame=''>0 0 0 0 0 0</pose>
                    <geometry>
                        <mesh>
                            <scale>1 1 1</scale>
                            <uri>meshes/finger_tip_right.stl</uri>
                        </mesh>
                    </geometry>
                    <material>
                        <ambient>1 0 0 1</ambient>
                        <diffuse>0.6 0.6 0.6 1</diffuse>
                        <specular>0.5 0.5 0.5 1</specular>
                        <emissive>0 0 0 0</emissive>
                    </material>
                </visual>
                <collision name='right_finger_tip_collision'>
                    <pose frame=''>0 0 0 0 0 0</pose>
                    <geometry>
                        <mesh>
                            <scale>1 1 1</scale>
                            <uri>meshes/finger_tip_right.stl</uri>
                        </mesh>
                    </geometry>
                </collision>
            </link>

        </model>
    </world>
</sdf>